

<robot name="spot">
  <link name="chassis">
  <contact>
      <lateral_friction value="1"/>
  </contact>
    <inertial>
      <origin rpy="0 0 0" xyz="0 0.03 0.043794"/>
       <mass value="13.715"/>
       <inertia ixx="0" ixy="0" ixz="0" iyy="0" iyz="0" izz="0"/>
    </inertial>
    <visual>
      <origin rpy="0 0 0" xyz="0 0 0.043794"/>
      <geometry>

                <mesh filename="meshes/base_link.STL" scale="1 1 1"/>
      </geometry>
       <material name="white">
        <color rgba="1 1 1 1"/>
      </material>
    </visual>
    <collision>
      <origin rpy="0 0 0" xyz="0 0 0"/>
      <geometry>

                <mesh filename="meshes/base_link.STL" scale="1 1 1"/>
      </geometry>
    </collision>
  </link>

     <link name="FR_hip_motor">
  <contact>
      <lateral_friction value="1"/>
  </contact>
    <inertial>
       <origin rpy="0 0 0" xyz="0.02 0 0"/>
       <mass value="1.095"/>
       <inertia ixx="0" ixy="0" ixz="0" iyy="0" iyz="0" izz="0"/>
    </inertial>

      <visual>
      <origin rpy="0 0 0" xyz="0 0 0"/>
      <geometry>
                <mesh filename="meshes/rf_hip_link.STL" scale="1 1 1"/>
      </geometry>
       <material name="white"/>
    </visual>

    <collision>
      <origin rpy="0 0 0" xyz="0 0 0"/>
      <geometry>
                <mesh filename="meshes/rf_hip_link.STL" scale="1 1 1"/>
      </geometry>
    </collision>
    </link>

    <joint name="FR_hip_motor_2_chassis_joint" type="continuous">
        <axis xyz="-1 0 0"/>
        <parent link="chassis"/>
        <child link="FR_hip_motor"/>
        <origin rpy="0 0 0" xyz="0.1325 -0.0798899999999921 -0.0342976400491808"/>
        <limit effort="100" velocity="100"/>
        <joint_properties damping=".0" friction=".0"/>
    </joint>

     <link name="FR_upper_leg">
  <contact>
      <lateral_friction value="1"/>
  </contact>
    <inertial>
     <origin rpy="0 0 0" xyz="0 -0.04 -0.04"/>
       <mass value="1.527"/>
       <inertia ixx="0" ixy="0" ixz="0" iyy="0" iyz="0" izz="0"/>
    </inertial>
       <visual>
      <origin rpy="0 0 0" xyz="0 0 0"/>
      <geometry>
                <mesh filename="meshes/rf_upper_link.STL" scale="1 1 1"/>
      </geometry>
      <material name="white"/>
    </visual>

    <collision>
      <origin rpy="0 0 0" xyz="0 0 0"/>
      <geometry>
                <mesh filename="meshes/rf_upper_link.STL" scale="1 1 1"/>
      </geometry>
    </collision>
    </link>

    <joint name="FR_upper_leg_2_hip_motor_joint" type="continuous">
        <axis xyz="0 0.999902556615601 -0.0139598450415945"/>
        <parent link="FR_hip_motor"/>
        <child link="FR_upper_leg"/>
        <origin rpy="0 0 0" xyz="0.0269999999999999 -0.0628123830812422 0.0138782034736232"/>
        <limit effort="100" velocity="100"/>
        <joint_properties damping=".0" friction=".0"/>
    </joint>

     <link name="FR_lower_leg">
  <contact>
      <lateral_friction value="1"/>
  </contact>
    <inertial>
      <origin rpy="0 0 0" xyz="0 -0.16 -0.02"/>
       <mass value="0.241"/>
       <inertia ixx="0" ixy="0" ixz="0" iyy="0" iyz="0" izz="0"/>
    </inertial>
       <visual>
      <origin rpy="0 0 0" xyz="0 0.0 0"/>
      <geometry>
                <mesh filename="meshes/rf_lower_link.STL" scale="1 1 1"/>
      </geometry>
       <material name="white"/>
    </visual>

    <collision>
      <origin rpy="0 1.57079 0" xyz="0 0.0 0"/>
      <geometry>
                <mesh filename="meshes/rf_lower_link.STL" scale="1 1 1"/>
      </geometry>
    </collision>

    </link>

    <joint name="FR_lower_leg_2_upper_leg_joint" type="continuous">
        <axis xyz="0 0.999902556615601 -0.0139598450415923"/>
        <parent link="FR_upper_leg"/>
        <child link="FR_lower_leg"/>

        <origin rpy="0 0 0" xyz="0 -0.00994944374978339 -0.13957706811974"/>
        <limit effort="100" velocity="100"/>
        <joint_properties damping=".0" friction=".0"/>
    </joint>


     <link name="FL_hip_motor">
  <contact>
      <lateral_friction value="1"/>
  </contact>
    <inertial>
     <origin rpy="0 0 0" xyz="-.02 0 0"/>
       <mass value="1.095"/>
       <inertia ixx="0" ixy="0" ixz="0" iyy="0" iyz="0" izz="0"/>
    </inertial>
    <visual>
      <origin rpy="0 0 0" xyz="0 0 0"/>
      <geometry>
                <mesh filename="meshes/lf_hip_link.STL" scale="1 1 1"/>
      </geometry>
       <material name="white">
      </material>
    </visual>

    <collision>
      <origin rpy="0 0 0" xyz="0 0 0"/>
      <geometry>
                <mesh filename="meshes/lf_hip_link.STL" scale="1 1 1"/>
      </geometry>
    </collision>

      </link>

   <joint name="FL_hip_motor_2_chassis_joint" type="continuous">
        <axis xyz="1 0 0"/>
        <parent link="chassis"/>
        <child link="FL_hip_motor"/>
        <origin rpy="0 0 0" xyz="0.1325 0.0798900000000003 -0.034297640049036"/>
        <limit effort="100" velocity="100"/>
        <joint_properties damping=".0" friction=".0"/>
    </joint>

  <link name="FL_upper_leg">
  <contact>
      <lateral_friction value="1"/>
  </contact>
    <inertial>
       <origin rpy="0 0 0" xyz="0 -0.04 -0.04"/>
       <mass value="1.527"/>
       <inertia ixx="0" ixy="0" ixz="0" iyy="0" iyz="0" izz="0"/>
    </inertial>
     <visual>
      <origin rpy="0 0 0" xyz="0 0 0"/>
      <geometry>

                <mesh filename="meshes/lf_upper_link.STL" scale="1 1 1"/>
      </geometry>
       <material name="white">
      </material>
    </visual>

     <collision>
      <origin rpy="0 0 0" xyz="0 0 0"/>
      <geometry>
                <mesh filename="meshes/lf_upper_link.STL" scale="1 1 1"/>
      </geometry>
    </collision>

    </link>


  <joint name="FL_upper_leg_2_hip_motor_joint" type="continuous">
        <axis xyz="0 0.9999025566156 -0.013959845041636"/>
        <parent link="FL_hip_motor"/>
        <child link="FL_upper_leg"/>
        <origin rpy="0 0 0" xyz="0.0270000000000001 0.063175339052324 0.0121192629983798"/>
        <limit effort="100" velocity="100"/>
        <joint_properties damping=".0" friction=".0"/>
    </joint>


  <link name="FL_lower_leg">
  <contact>
      <lateral_friction value="1"/>
  </contact>
    <inertial>
      <origin rpy="0 0 0" xyz="0 -0.16 -0.02"/>
       <mass value="0.241"/>
       <inertia ixx="0" ixy="0" ixz="0" iyy="0" iyz="0" izz="0"/>
    </inertial>
   <visual>
      <origin rpy="0 0 0" xyz="0 0 0"/>
      <geometry>
                <mesh filename="meshes/lf_lower_link.STL" scale="1 1 1"/>
      </geometry>
       <material name="white">
      </material>
    </visual>

     <collision>
      <origin rpy="0 0 0" xyz="0 0 0"/>
      <geometry>
                <mesh filename="meshes/lf_lower_link.STL" scale="1 1 1"/>
      </geometry>
    </collision>

    </link>

  <joint name="FL_lower_leg_2_upper_leg_joint" type="continuous">
        <axis xyz="0 0.9999025566156 -0.0139598450416295"/>
        <parent link="FL_upper_leg"/>
        <child link="FL_lower_leg"/>
        <origin rpy="0 0 0" xyz="0 0.00604899715606039 -0.139800425640405"/>
        <limit effort="100" velocity="100"/>
        <joint_properties damping=".0" friction=".0"/>
    </joint>






     <link name="RR_hip_motor">
  <contact>
      <lateral_friction value="1"/>
  </contact>
    <inertial>
      <origin rpy="0 0 0" xyz="0.02 0 0"/>
       <mass value="1.095"/>
       <inertia ixx="0" ixy="0" ixz="0" iyy="0" iyz="0" izz="0"/>
    </inertial>

      <visual>
      <origin rpy="0 0 0" xyz="0 0 0"/>
      <geometry>
                <mesh filename="meshes/rh_hip_link.STL" scale="1 1 1"/>
      </geometry>
       <material name="white"/>
    </visual>

     <collision>
      <origin rpy="0 0 0" xyz="0 0 0"/>
      <geometry>
                <mesh filename="meshes/rh_hip_link.STL" scale="1 1 1"/>
      </geometry>
    </collision>

    </link>

    <joint name="RR_hip_motor_2_chassis_joint" type="continuous">
        <axis xyz="-1 0 0"/>
        <parent link="chassis"/>
        <child link="RR_hip_motor"/>
        <origin rpy="0 0 0" xyz="-0.132499999999999 -0.0798900000000018 -0.0342976400491642"/>
        <limit effort="100" velocity="100"/>
        <joint_properties damping=".0" friction=".0"/>
    </joint>

     <link name="RR_upper_leg">
  <contact>
      <lateral_friction value="1"/>
  </contact>
    <inertial>
     <origin rpy="0 0 0" xyz="0 -0.04 -0.04"/>
       <mass value="1.527"/>
       <inertia ixx="0" ixy="0" ixz="0" iyy="0" iyz="0" izz="0"/>
    </inertial>
       <visual>
      <origin rpy="0 0 0" xyz="0 0 0"/>
      <geometry>
                <mesh filename="meshes/rh_upper_link.STL" scale="1 1 1"/>
      </geometry>
       <material name="white"/>
    </visual>

    <collision>
      <origin rpy="0 0 0" xyz="0 0 0"/>
      <geometry>
                <mesh filename="meshes/rh_upper_link.STL" scale="1 1 1"/>
      </geometry>
    </collision>

    </link>

    <joint name="RR_upper_leg_2_hip_motor_joint" type="continuous">
        <axis xyz="0 1 0"/>
        <parent link="RR_hip_motor"/>
        <child link="RR_upper_leg"/>
        <origin rpy="0 0 0" xyz="-0.0719999999999999 -0.0630000000000001 0.013"/>
        <limit effort="100" velocity="100"/>
        <joint_properties damping=".0" friction=".0"/>
    </joint>

     <link name="RR_lower_leg">
  <contact>
      <lateral_friction value="1"/>
  </contact>
    <inertial>
      <origin rpy="0 0 0" xyz="0 -0.16 -0.02"/>
       <mass value="0.241"/>
       <inertia ixx="0" ixy="0" ixz="0" iyy="0" iyz="0" izz="0"/>
    </inertial>
       <visual>
      <origin rpy="0 0 0" xyz="0 0 0"/>
      <geometry>
                <mesh filename="meshes/rh_lower_link.STL" scale="1 1 1"/>
      </geometry>
       <material name="white"/>
    </visual>

     <collision>
      <origin rpy="0 1.57079 0" xyz="0 0 0"/>
      <geometry>
                <mesh filename="meshes/rh_lower_link.STL" scale="1 1 1"/>
      </geometry>
    </collision>

    </link>

    <joint name="RR_lower_leg_2_upper_leg_joint" type="continuous">
        <axis xyz="0 1 0"/>
        <parent link="RR_upper_leg"/>
        <child link="RR_lower_leg"/>
        <origin rpy="0 0 0" xyz="0 -0.00799999999999998 -0.139702359950835"/>
        <limit effort="100" velocity="100"/>
        <joint_properties damping=".0" friction=".0"/>
    </joint>


     <link name="RL_hip_motor">
  <contact>
      <lateral_friction value="1"/>
  </contact>
    <inertial>
      <origin rpy="0 0 0" xyz="-.02 0 0"/>
       <mass value="1.095"/>
       <inertia ixx="0" ixy="0" ixz="0" iyy="0" iyz="0" izz="0"/>
    </inertial>
    <visual>
      <origin rpy="0 0 0" xyz="0 0 0"/>
      <geometry>
                <mesh filename="meshes/lh_hip_link.STL" scale="1 1 1"/>
      </geometry>
       <material name="white"/>
    </visual>

    <collision>
      <origin rpy="0 0 0" xyz="0 0 0"/>
      <geometry>
                <mesh filename="meshes/lh_hip_link.STL" scale="1 1 1"/>
      </geometry>
    </collision>

      </link>

   <joint name="RL_hip_motor_2_chassis_joint" type="continuous">
        <axis xyz="1 0 0"/>
        <parent link="chassis"/>
        <child link="RL_hip_motor"/>

        <origin rpy="0 0 0" xyz="-0.113675317925363 0.0876111412863929 -0.0336879615739561"/>
        <limit effort="100" velocity="100"/>
        <joint_properties damping=".0" friction=".0"/>
    </joint>

  <link name="RL_upper_leg">
  <contact>
      <lateral_friction value="1"/>
  </contact>
    <inertial>
      <origin rpy="0 0 0" xyz="0 -0.04 -0.04"/>
       <mass value="1.527"/>
       <inertia ixx="0" ixy="0" ixz="0" iyy="0" iyz="0" izz="0"/>
    </inertial>
     <visual>
      <origin rpy="0 0 0" xyz="0 0 0"/>
      <geometry>
                <mesh filename="meshes/lh_upper_link.STL" scale="1 1 1"/>
      </geometry>
       <material name="white"/>
    </visual>

    <collision>
      <origin rpy="0 0 0" xyz="0 0 0"/>
      <geometry>
                <mesh filename="meshes/lh_upper_link.STL" scale="1 1 1"/>
      </geometry>
    </collision>

    </link>


  <joint name="RL_upper_leg_2_hip_motor_joint" type="continuous">
        <axis xyz="0 1 0"/>
        <parent link="RL_hip_motor"/>
        <child link="RL_upper_leg"/>
        <origin rpy="0 0 0" xyz="-0.072 0.063 0.0130000000000001"/>
        <limit effort="100" velocity="100"/>
        <joint_properties damping=".0" friction=".0"/>
    </joint>


  <link name="RL_lower_leg">
  <contact>
      <lateral_friction value="1"/>
  </contact>
    <inertial>
      <origin rpy="0 0 0" xyz="0 -0.16 -0.02"/>
       <mass value="0.241"/>
       <inertia ixx="0" ixy="0" ixz="0" iyy="0" iyz="0" izz="0"/>
    </inertial>
   <visual>
      <origin rpy="0 0 0" xyz="0 0 0"/>
      <geometry>
                <mesh filename="meshes/lh_lower_link.STL" scale="1 1 1"/>
      </geometry>
       <material name="white"/>
    </visual>

    <collision>
      <origin rpy="0 0 0" xyz="0 0 0"/>
      <geometry>
                <mesh filename="meshes/lh_lower_link.STL" scale="1 1 1"/>
      </geometry>
    </collision>

    </link>

  <joint name="RL_lower_leg_2_upper_leg_joint" type="continuous">
        <axis xyz="0 1 0"/>
        <parent link="RL_upper_leg"/>
        <child link="RL_lower_leg"/>
        <origin rpy="0 0 0" xyz="0 0.008 -0.1397"/>
        <limit effort="100" velocity="100"/>
        <joint_properties damping=".0" friction=".0"/>
    </joint>



</robot>

